2019-10-11 19:04:04,681 INFO: Fate startup [in C:\Users\Evan\documents\fate\app\__init__.py:46]
2019-10-11 19:07:11,423 INFO: Fate startup [in C:\Users\Evan\documents\fate\app\__init__.py:46]
2019-10-11 19:07:43,141 INFO: Fate startup [in C:\Users\Evan\documents\fate\app\__init__.py:46]
2019-10-11 19:09:05,245 INFO: Fate startup [in C:\Users\Evan\documents\fate\app\__init__.py:46]
2019-10-11 19:13:28,737 INFO: Fate startup [in C:\Users\Evan\documents\fate\app\__init__.py:46]
2019-10-11 19:13:58,647 INFO: Fate startup [in C:\Users\Evan\documents\fate\app\__init__.py:46]
2019-10-11 19:14:56,924 INFO: Fate startup [in C:\Users\Evan\documents\fate\app\__init__.py:46]
2019-10-11 19:16:50,534 INFO: Fate startup [in C:\Users\Evan\documents\fate\app\__init__.py:46]
2019-10-11 19:18:55,412 INFO: Fate startup [in C:\Users\Evan\documents\fate\app\__init__.py:46]
2019-10-11 19:19:19,258 INFO: Fate startup [in C:\Users\Evan\documents\fate\app\__init__.py:46]
2019-10-11 19:23:33,834 INFO: Fate startup [in C:\Users\Evan\documents\fate\app\__init__.py:46]
2019-10-11 19:24:33,944 INFO: Fate startup [in C:\Users\Evan\documents\fate\app\__init__.py:46]
2019-10-11 19:26:28,876 INFO: Fate startup [in C:\Users\Evan\documents\fate\app\__init__.py:46]
2019-10-11 19:29:04,752 INFO: Fate startup [in C:\Users\Evan\documents\fate\app\__init__.py:46]
2019-10-11 19:29:19,143 ERROR: Exception on /add_recipes/Alchemy [POST] [in c:\users\evan\anaconda3\envs\fate\lib\site-packages\flask\app.py:1891]
Traceback (most recent call last):
  File "c:\users\evan\anaconda3\envs\fate\lib\site-packages\flask\app.py", line 2446, in wsgi_app
    response = self.full_dispatch_request()
  File "c:\users\evan\anaconda3\envs\fate\lib\site-packages\flask\app.py", line 1951, in full_dispatch_request
    rv = self.handle_user_exception(e)
  File "c:\users\evan\anaconda3\envs\fate\lib\site-packages\flask\app.py", line 1820, in handle_user_exception
    reraise(exc_type, exc_value, tb)
  File "c:\users\evan\anaconda3\envs\fate\lib\site-packages\flask\_compat.py", line 39, in reraise
    raise value
  File "c:\users\evan\anaconda3\envs\fate\lib\site-packages\flask\app.py", line 1949, in full_dispatch_request
    rv = self.dispatch_request()
  File "c:\users\evan\anaconda3\envs\fate\lib\site-packages\flask\app.py", line 1935, in dispatch_request
    return self.view_functions[rule.endpoint](**req.view_args)
  File "c:\users\evan\anaconda3\envs\fate\lib\site-packages\flask_login\utils.py", line 261, in decorated_view
    return func(*args, **kwargs)
  File "C:\Users\Evan\documents\fate\app\routes.py", line 99, in add_recipes
    if form.validate_on_submit():
  File "c:\users\evan\anaconda3\envs\fate\lib\site-packages\flask_wtf\form.py", line 101, in validate_on_submit
    return self.is_submitted() and self.validate()
  File "c:\users\evan\anaconda3\envs\fate\lib\site-packages\wtforms\form.py", line 310, in validate
    return super(Form, self).validate(extra)
  File "c:\users\evan\anaconda3\envs\fate\lib\site-packages\wtforms\form.py", line 152, in validate
    if not field.validate(self, extra):
  File "c:\users\evan\anaconda3\envs\fate\lib\site-packages\wtforms\fields\core.py", line 195, in validate
    self.pre_validate(form)
  File "c:\users\evan\anaconda3\envs\fate\lib\site-packages\wtforms\fields\core.py", line 505, in pre_validate
    values = list(c[0] for c in self.choices)
TypeError: 'NoneType' object is not iterable
2019-10-11 19:29:50,281 INFO: Fate startup [in C:\Users\Evan\documents\fate\app\__init__.py:46]
2019-10-11 19:31:20,949 INFO: Fate startup [in C:\Users\Evan\documents\fate\app\__init__.py:46]
2019-10-11 19:32:08,737 INFO: Fate startup [in C:\Users\Evan\documents\fate\app\__init__.py:46]
2019-10-11 19:35:41,340 INFO: Fate startup [in C:\Users\Evan\documents\fate\app\__init__.py:46]
2019-10-11 19:36:03,189 INFO: Fate startup [in C:\Users\Evan\documents\fate\app\__init__.py:46]
2019-10-11 19:39:40,949 INFO: Fate startup [in C:\Users\Evan\documents\fate\app\__init__.py:46]
2019-10-11 19:39:57,901 INFO: Fate startup [in C:\Users\Evan\documents\fate\app\__init__.py:46]
2019-10-11 19:50:13,912 INFO: Fate startup [in C:\Users\Evan\documents\fate\app\__init__.py:46]
2019-10-11 19:51:12,323 INFO: Fate startup [in C:\Users\Evan\documents\fate\app\__init__.py:46]
2019-10-11 22:13:48,386 INFO: Fate startup [in C:\Users\Evan\documents\fate\app\__init__.py:46]
2019-10-11 22:13:52,857 INFO: Fate startup [in C:\Users\Evan\documents\fate\app\__init__.py:46]
2019-10-11 22:16:51,958 INFO: Fate startup [in C:\Users\Evan\documents\fate\app\__init__.py:46]
2019-10-11 22:26:25,383 INFO: Fate startup [in C:\Users\Evan\documents\fate\app\__init__.py:46]
2019-10-11 22:31:52,737 INFO: Fate startup [in C:\Users\Evan\documents\fate\app\__init__.py:46]
2019-10-11 22:35:09,137 INFO: Fate startup [in C:\Users\Evan\documents\fate\app\__init__.py:46]
2019-10-11 22:41:41,607 INFO: Fate startup [in C:\Users\Evan\documents\fate\app\__init__.py:46]
2019-10-11 22:42:11,436 INFO: Fate startup [in C:\Users\Evan\documents\fate\app\__init__.py:46]
2019-10-11 22:43:34,344 INFO: Fate startup [in C:\Users\Evan\documents\fate\app\__init__.py:46]
2019-10-11 22:44:51,807 INFO: Fate startup [in C:\Users\Evan\documents\fate\app\__init__.py:46]
