2019-10-10 22:16:55,105 INFO: Fate startup [in C:\Users\Evan\documents\fate\app\__init__.py:44]
2019-10-10 22:17:01,154 INFO: Fate startup [in C:\Users\Evan\documents\fate\app\__init__.py:44]
2019-10-10 22:17:59,715 INFO: Fate startup [in C:\Users\Evan\documents\fate\app\__init__.py:44]
2019-10-10 22:18:03,327 INFO: Fate startup [in C:\Users\Evan\documents\fate\app\__init__.py:44]
2019-10-10 22:18:10,244 INFO: Fate startup [in C:\Users\Evan\documents\fate\app\__init__.py:44]
2019-10-10 22:19:39,400 INFO: Fate startup [in C:\Users\Evan\documents\fate\app\__init__.py:44]
2019-10-10 22:22:53,208 INFO: Fate startup [in C:\Users\Evan\documents\fate\app\__init__.py:44]
2019-10-10 22:25:38,919 INFO: Fate startup [in C:\Users\Evan\documents\fate\app\__init__.py:44]
2019-10-10 22:27:21,366 INFO: Fate startup [in C:\Users\Evan\documents\fate\app\__init__.py:44]
2019-10-10 22:30:13,111 INFO: Fate startup [in C:\Users\Evan\documents\fate\app\__init__.py:44]
2019-10-10 22:31:35,252 INFO: Fate startup [in C:\Users\Evan\documents\fate\app\__init__.py:44]
2019-10-10 22:35:11,259 INFO: Fate startup [in C:\Users\Evan\documents\fate\app\__init__.py:44]
2019-10-10 22:40:12,283 INFO: Fate startup [in C:\Users\Evan\documents\fate\app\__init__.py:44]
2019-10-10 22:44:33,218 INFO: Fate startup [in C:\Users\Evan\documents\fate\app\__init__.py:44]
2019-10-10 22:46:06,436 INFO: Fate startup [in C:\Users\Evan\documents\fate\app\__init__.py:44]
2019-10-10 22:47:37,280 INFO: Fate startup [in C:\Users\Evan\documents\fate\app\__init__.py:44]
2019-10-10 22:48:20,619 INFO: Fate startup [in C:\Users\Evan\documents\fate\app\__init__.py:44]
2019-10-10 22:58:32,977 INFO: Fate startup [in C:\Users\Evan\documents\fate\app\__init__.py:44]
2019-10-10 23:00:18,600 INFO: Fate startup [in C:\Users\Evan\documents\fate\app\__init__.py:44]
2019-10-10 23:01:29,034 INFO: Fate startup [in C:\Users\Evan\documents\fate\app\__init__.py:44]
2019-10-10 23:02:26,107 INFO: Fate startup [in C:\Users\Evan\documents\fate\app\__init__.py:44]
2019-10-10 23:02:40,603 INFO: Fate startup [in C:\Users\Evan\documents\fate\app\__init__.py:44]
2019-10-10 23:04:30,890 INFO: Fate startup [in C:\Users\Evan\documents\fate\app\__init__.py:44]
2019-10-10 23:06:55,162 INFO: Fate startup [in C:\Users\Evan\documents\fate\app\__init__.py:44]
2019-10-10 23:07:42,543 INFO: Fate startup [in C:\Users\Evan\documents\fate\app\__init__.py:44]
2019-10-10 23:08:35,893 INFO: Fate startup [in C:\Users\Evan\documents\fate\app\__init__.py:44]
2019-10-10 23:08:41,126 INFO: Fate startup [in C:\Users\Evan\documents\fate\app\__init__.py:44]
2019-10-10 23:18:06,155 INFO: Fate startup [in C:\Users\Evan\documents\fate\app\__init__.py:44]
2019-10-10 23:18:36,301 INFO: Fate startup [in C:\Users\Evan\documents\fate\app\__init__.py:44]
2019-10-10 23:20:25,800 INFO: Fate startup [in C:\Users\Evan\documents\fate\app\__init__.py:44]
2019-10-10 23:28:56,900 INFO: Fate startup [in C:\Users\Evan\documents\fate\app\__init__.py:44]
2019-10-10 23:29:00,276 INFO: Fate startup [in C:\Users\Evan\documents\fate\app\__init__.py:44]
2019-10-10 23:39:06,226 INFO: Fate startup [in C:\Users\Evan\documents\fate\app\__init__.py:44]
2019-10-10 23:48:26,065 INFO: Fate startup [in C:\Users\Evan\documents\fate\app\__init__.py:44]
2019-10-10 23:52:28,040 INFO: Fate startup [in C:\Users\Evan\documents\fate\app\__init__.py:44]
2019-10-11 00:00:02,944 INFO: Fate startup [in C:\Users\Evan\documents\fate\app\__init__.py:44]
2019-10-11 00:31:27,769 INFO: Fate startup [in C:\Users\Evan\documents\fate\app\__init__.py:44]
2019-10-11 00:31:37,968 INFO: Fate startup [in C:\Users\Evan\documents\fate\app\__init__.py:44]
2019-10-11 00:31:51,313 INFO: Fate startup [in C:\Users\Evan\documents\fate\app\__init__.py:44]
2019-10-11 00:31:57,052 INFO: Fate startup [in C:\Users\Evan\documents\fate\app\__init__.py:44]
2019-10-11 00:32:00,342 INFO: Fate startup [in C:\Users\Evan\documents\fate\app\__init__.py:44]
2019-10-11 00:32:05,415 INFO: Fate startup [in C:\Users\Evan\documents\fate\app\__init__.py:44]
2019-10-11 01:43:38,468 INFO: Fate startup [in C:\Users\Evan\documents\fate\app\__init__.py:44]
2019-10-11 01:43:49,775 ERROR: Exception on /recipes/Alchemy [GET] [in c:\users\evan\anaconda3\envs\fate\lib\site-packages\flask\app.py:1891]
Traceback (most recent call last):
  File "c:\users\evan\anaconda3\envs\fate\lib\site-packages\sqlalchemy\engine\base.py", line 1249, in _execute_context
    cursor, statement, parameters, context
  File "c:\users\evan\anaconda3\envs\fate\lib\site-packages\sqlalchemy\engine\default.py", line 580, in do_execute
    cursor.execute(statement, parameters)
sqlite3.OperationalError: no such column: user.profession_one

The above exception was the direct cause of the following exception:

Traceback (most recent call last):
  File "c:\users\evan\anaconda3\envs\fate\lib\site-packages\flask\app.py", line 2446, in wsgi_app
    response = self.full_dispatch_request()
  File "c:\users\evan\anaconda3\envs\fate\lib\site-packages\flask\app.py", line 1951, in full_dispatch_request
    rv = self.handle_user_exception(e)
  File "c:\users\evan\anaconda3\envs\fate\lib\site-packages\flask\app.py", line 1820, in handle_user_exception
    reraise(exc_type, exc_value, tb)
  File "c:\users\evan\anaconda3\envs\fate\lib\site-packages\flask\_compat.py", line 39, in reraise
    raise value
  File "c:\users\evan\anaconda3\envs\fate\lib\site-packages\flask\app.py", line 1947, in full_dispatch_request
    rv = self.preprocess_request()
  File "c:\users\evan\anaconda3\envs\fate\lib\site-packages\flask\app.py", line 2241, in preprocess_request
    rv = func()
  File "C:\Users\Evan\documents\fate\app\routes.py", line 10, in before_request
    if current_user.is_authenticated:
  File "c:\users\evan\anaconda3\envs\fate\lib\site-packages\werkzeug\local.py", line 348, in __getattr__
    return getattr(self._get_current_object(), name)
  File "c:\users\evan\anaconda3\envs\fate\lib\site-packages\werkzeug\local.py", line 307, in _get_current_object
    return self.__local()
  File "c:\users\evan\anaconda3\envs\fate\lib\site-packages\flask_login\utils.py", line 26, in <lambda>
    current_user = LocalProxy(lambda: _get_user())
  File "c:\users\evan\anaconda3\envs\fate\lib\site-packages\flask_login\utils.py", line 335, in _get_user
    current_app.login_manager._load_user()
  File "c:\users\evan\anaconda3\envs\fate\lib\site-packages\flask_login\login_manager.py", line 359, in _load_user
    return self.reload_user()
  File "c:\users\evan\anaconda3\envs\fate\lib\site-packages\flask_login\login_manager.py", line 321, in reload_user
    user = self.user_callback(user_id)
  File "C:\Users\Evan\documents\fate\app\models.py", line 55, in load_user
    return User.query.get(int(id))
  File "c:\users\evan\anaconda3\envs\fate\lib\site-packages\sqlalchemy\orm\query.py", line 959, in get
    return self._get_impl(ident, loading.load_on_pk_identity)
  File "c:\users\evan\anaconda3\envs\fate\lib\site-packages\sqlalchemy\orm\query.py", line 1069, in _get_impl
    return db_load_fn(self, primary_key_identity)
  File "c:\users\evan\anaconda3\envs\fate\lib\site-packages\sqlalchemy\orm\loading.py", line 282, in load_on_pk_identity
    return q.one()
  File "c:\users\evan\anaconda3\envs\fate\lib\site-packages\sqlalchemy\orm\query.py", line 3300, in one
    ret = self.one_or_none()
  File "c:\users\evan\anaconda3\envs\fate\lib\site-packages\sqlalchemy\orm\query.py", line 3269, in one_or_none
    ret = list(self)
  File "c:\users\evan\anaconda3\envs\fate\lib\site-packages\sqlalchemy\orm\query.py", line 3342, in __iter__
    return self._execute_and_instances(context)
  File "c:\users\evan\anaconda3\envs\fate\lib\site-packages\sqlalchemy\orm\query.py", line 3367, in _execute_and_instances
    result = conn.execute(querycontext.statement, self._params)
  File "c:\users\evan\anaconda3\envs\fate\lib\site-packages\sqlalchemy\engine\base.py", line 988, in execute
    return meth(self, multiparams, params)
  File "c:\users\evan\anaconda3\envs\fate\lib\site-packages\sqlalchemy\sql\elements.py", line 287, in _execute_on_connection
    return connection._execute_clauseelement(self, multiparams, params)
  File "c:\users\evan\anaconda3\envs\fate\lib\site-packages\sqlalchemy\engine\base.py", line 1107, in _execute_clauseelement
    distilled_params,
  File "c:\users\evan\anaconda3\envs\fate\lib\site-packages\sqlalchemy\engine\base.py", line 1253, in _execute_context
    e, statement, parameters, cursor, context
  File "c:\users\evan\anaconda3\envs\fate\lib\site-packages\sqlalchemy\engine\base.py", line 1473, in _handle_dbapi_exception
    util.raise_from_cause(sqlalchemy_exception, exc_info)
  File "c:\users\evan\anaconda3\envs\fate\lib\site-packages\sqlalchemy\util\compat.py", line 398, in raise_from_cause
    reraise(type(exception), exception, tb=exc_tb, cause=cause)
  File "c:\users\evan\anaconda3\envs\fate\lib\site-packages\sqlalchemy\util\compat.py", line 152, in reraise
    raise value.with_traceback(tb)
  File "c:\users\evan\anaconda3\envs\fate\lib\site-packages\sqlalchemy\engine\base.py", line 1249, in _execute_context
    cursor, statement, parameters, context
  File "c:\users\evan\anaconda3\envs\fate\lib\site-packages\sqlalchemy\engine\default.py", line 580, in do_execute
    cursor.execute(statement, parameters)
sqlalchemy.exc.OperationalError: (sqlite3.OperationalError) no such column: user.profession_one
[SQL: SELECT user.id AS user_id, user.username AS user_username, user.email AS user_email, user.password_hash AS user_password_hash, user.about_me AS user_about_me, user.last_seen AS user_last_seen, user.profession_one AS user_profession_one, user.profession_two AS user_profession_two 
FROM user 
WHERE user.id = ?]
[parameters: (1,)]
(Background on this error at: http://sqlalche.me/e/e3q8)
