2019-10-11 17:50:04,862 ERROR: Exception on /user/Malthador [GET] [in c:\users\evan\anaconda3\envs\fate\lib\site-packages\flask\app.py:1891]
Traceback (most recent call last):
  File "c:\users\evan\anaconda3\envs\fate\lib\site-packages\flask\app.py", line 2446, in wsgi_app
    response = self.full_dispatch_request()
  File "c:\users\evan\anaconda3\envs\fate\lib\site-packages\flask\app.py", line 1951, in full_dispatch_request
    rv = self.handle_user_exception(e)
  File "c:\users\evan\anaconda3\envs\fate\lib\site-packages\flask\app.py", line 1820, in handle_user_exception
    reraise(exc_type, exc_value, tb)
  File "c:\users\evan\anaconda3\envs\fate\lib\site-packages\flask\_compat.py", line 39, in reraise
    raise value
  File "c:\users\evan\anaconda3\envs\fate\lib\site-packages\flask\app.py", line 1949, in full_dispatch_request
    rv = self.dispatch_request()
  File "c:\users\evan\anaconda3\envs\fate\lib\site-packages\flask\app.py", line 1935, in dispatch_request
    return self.view_functions[rule.endpoint](**req.view_args)
  File "C:\Users\Evan\documents\fate\app\routes.py", line 57, in user
    return render_template('user.html', user=user)
  File "c:\users\evan\anaconda3\envs\fate\lib\site-packages\flask\templating.py", line 140, in render_template
    ctx.app,
  File "c:\users\evan\anaconda3\envs\fate\lib\site-packages\flask\templating.py", line 120, in _render
    rv = template.render(context)
  File "c:\users\evan\anaconda3\envs\fate\lib\site-packages\jinja2\asyncsupport.py", line 76, in render
    return original_render(self, *args, **kwargs)
  File "c:\users\evan\anaconda3\envs\fate\lib\site-packages\jinja2\environment.py", line 1008, in render
    return self.environment.handle_exception(exc_info, True)
  File "c:\users\evan\anaconda3\envs\fate\lib\site-packages\jinja2\environment.py", line 780, in handle_exception
    reraise(exc_type, exc_value, tb)
  File "c:\users\evan\anaconda3\envs\fate\lib\site-packages\jinja2\_compat.py", line 37, in reraise
    raise value.with_traceback(tb)
  File "C:\Users\Evan\documents\fate\app\templates\user.html", line 1, in top-level template code
    {% extends "base.html" %}
  File "c:\users\evan\anaconda3\envs\fate\lib\site-packages\jinja2\environment.py", line 1005, in render
    return concat(self.root_render_func(self.new_context(vars)))
  File "C:\Users\Evan\documents\fate\app\templates\user.html", line 14, in root
    <p><a href="{{ url_for('edit_profile') }}">Edit your profile</a></p>
  File "C:\Users\Evan\documents\fate\app\templates\base.html", line 14, in root
    <div class="collapse navbar-collapse" id="navbarText">
  File "c:\users\evan\anaconda3\envs\fate\lib\site-packages\flask_bootstrap\templates\bootstrap\base.html", line 10, in root
    {%- endblock metas %}
  File "c:\users\evan\anaconda3\envs\fate\lib\site-packages\flask_bootstrap\templates\bootstrap\base.html", line 20, in block_doc
    {%- endblock head %}
  File "c:\users\evan\anaconda3\envs\fate\lib\site-packages\flask_bootstrap\templates\bootstrap\base.html", line 40, in block_html
  File "c:\users\evan\anaconda3\envs\fate\lib\site-packages\flask_bootstrap\templates\bootstrap\base.html", line 93, in block_body
  File "C:\Users\Evan\documents\fate\app\templates\base.html", line 85, in block_content
  File "C:\Users\Evan\documents\fate\app\templates\user.html", line 43, in block_app_content
  File "c:\users\evan\anaconda3\envs\fate\lib\site-packages\jinja2\runtime.py", line 262, in call
    return __obj(*args, **kwargs)
  File "c:\users\evan\anaconda3\envs\fate\lib\site-packages\flask\helpers.py", line 370, in url_for
    return appctx.app.handle_url_build_error(error, endpoint, values)
  File "c:\users\evan\anaconda3\envs\fate\lib\site-packages\flask\app.py", line 2215, in handle_url_build_error
    reraise(exc_type, exc_value, tb)
  File "c:\users\evan\anaconda3\envs\fate\lib\site-packages\flask\_compat.py", line 39, in reraise
    raise value
  File "c:\users\evan\anaconda3\envs\fate\lib\site-packages\flask\helpers.py", line 358, in url_for
    endpoint, values, method=method, force_external=external
  File "c:\users\evan\anaconda3\envs\fate\lib\site-packages\werkzeug\routing.py", line 2020, in build
    raise BuildError(endpoint, values, method, self)
werkzeug.routing.BuildError: Could not build url for endpoint 'recipes'. Did you forget to specify values ['profession']?
2019-10-11 17:53:42,142 INFO: Fate startup [in C:\Users\Evan\documents\fate\app\__init__.py:46]
2019-10-11 17:55:40,817 INFO: Fate startup [in C:\Users\Evan\documents\fate\app\__init__.py:46]
2019-10-11 18:11:42,389 INFO: Fate startup [in C:\Users\Evan\documents\fate\app\__init__.py:46]
2019-10-11 18:13:12,959 INFO: Fate startup [in C:\Users\Evan\documents\fate\app\__init__.py:46]
2019-10-11 18:15:24,665 INFO: Fate startup [in C:\Users\Evan\documents\fate\app\__init__.py:46]
2019-10-11 18:15:53,997 INFO: Fate startup [in C:\Users\Evan\documents\fate\app\__init__.py:46]
2019-10-11 18:16:35,701 ERROR: Exception on /add_recipes [POST] [in c:\users\evan\anaconda3\envs\fate\lib\site-packages\flask\app.py:1891]
Traceback (most recent call last):
  File "c:\users\evan\anaconda3\envs\fate\lib\site-packages\flask\app.py", line 2446, in wsgi_app
    response = self.full_dispatch_request()
  File "c:\users\evan\anaconda3\envs\fate\lib\site-packages\flask\app.py", line 1952, in full_dispatch_request
    return self.finalize_request(rv)
  File "c:\users\evan\anaconda3\envs\fate\lib\site-packages\flask\app.py", line 1969, in finalize_request
    response = self.process_response(response)
  File "c:\users\evan\anaconda3\envs\fate\lib\site-packages\flask\app.py", line 2268, in process_response
    self.session_interface.save_session(self, ctx.session, response)
  File "c:\users\evan\anaconda3\envs\fate\lib\site-packages\flask\sessions.py", line 378, in save_session
    val = self.get_signing_serializer(app).dumps(dict(session))
  File "c:\users\evan\anaconda3\envs\fate\lib\site-packages\itsdangerous\serializer.py", line 166, in dumps
    payload = want_bytes(self.dump_payload(obj))
  File "c:\users\evan\anaconda3\envs\fate\lib\site-packages\itsdangerous\url_safe.py", line 42, in dump_payload
    json = super(URLSafeSerializerMixin, self).dump_payload(obj)
  File "c:\users\evan\anaconda3\envs\fate\lib\site-packages\itsdangerous\serializer.py", line 133, in dump_payload
    return want_bytes(self.serializer.dumps(obj, **self.serializer_kwargs))
  File "c:\users\evan\anaconda3\envs\fate\lib\site-packages\flask\json\tag.py", line 305, in dumps
    return dumps(self.tag(value), separators=(",", ":"))
  File "c:\users\evan\anaconda3\envs\fate\lib\site-packages\flask\json\__init__.py", line 211, in dumps
    rv = _json.dumps(obj, **kwargs)
  File "c:\users\evan\anaconda3\envs\fate\lib\json\__init__.py", line 238, in dumps
    **kw).encode(obj)
  File "c:\users\evan\anaconda3\envs\fate\lib\json\encoder.py", line 199, in encode
    chunks = self.iterencode(o, _one_shot=True)
  File "c:\users\evan\anaconda3\envs\fate\lib\json\encoder.py", line 257, in iterencode
    return _iterencode(o, 0)
  File "c:\users\evan\anaconda3\envs\fate\lib\site-packages\flask\json\__init__.py", line 100, in default
    return _json.JSONEncoder.default(self, o)
  File "c:\users\evan\anaconda3\envs\fate\lib\json\encoder.py", line 179, in default
    raise TypeError(f'Object of type {o.__class__.__name__} '
TypeError: Object of type AddRecipeForm is not JSON serializable
2019-10-11 18:16:59,707 ERROR: Exception on /add_recipes [POST] [in c:\users\evan\anaconda3\envs\fate\lib\site-packages\flask\app.py:1891]
Traceback (most recent call last):
  File "c:\users\evan\anaconda3\envs\fate\lib\site-packages\flask\app.py", line 2446, in wsgi_app
    response = self.full_dispatch_request()
  File "c:\users\evan\anaconda3\envs\fate\lib\site-packages\flask\app.py", line 1952, in full_dispatch_request
    return self.finalize_request(rv)
  File "c:\users\evan\anaconda3\envs\fate\lib\site-packages\flask\app.py", line 1969, in finalize_request
    response = self.process_response(response)
  File "c:\users\evan\anaconda3\envs\fate\lib\site-packages\flask\app.py", line 2268, in process_response
    self.session_interface.save_session(self, ctx.session, response)
  File "c:\users\evan\anaconda3\envs\fate\lib\site-packages\flask\sessions.py", line 378, in save_session
    val = self.get_signing_serializer(app).dumps(dict(session))
  File "c:\users\evan\anaconda3\envs\fate\lib\site-packages\itsdangerous\serializer.py", line 166, in dumps
    payload = want_bytes(self.dump_payload(obj))
  File "c:\users\evan\anaconda3\envs\fate\lib\site-packages\itsdangerous\url_safe.py", line 42, in dump_payload
    json = super(URLSafeSerializerMixin, self).dump_payload(obj)
  File "c:\users\evan\anaconda3\envs\fate\lib\site-packages\itsdangerous\serializer.py", line 133, in dump_payload
    return want_bytes(self.serializer.dumps(obj, **self.serializer_kwargs))
  File "c:\users\evan\anaconda3\envs\fate\lib\site-packages\flask\json\tag.py", line 305, in dumps
    return dumps(self.tag(value), separators=(",", ":"))
  File "c:\users\evan\anaconda3\envs\fate\lib\site-packages\flask\json\__init__.py", line 211, in dumps
    rv = _json.dumps(obj, **kwargs)
  File "c:\users\evan\anaconda3\envs\fate\lib\json\__init__.py", line 238, in dumps
    **kw).encode(obj)
  File "c:\users\evan\anaconda3\envs\fate\lib\json\encoder.py", line 199, in encode
    chunks = self.iterencode(o, _one_shot=True)
  File "c:\users\evan\anaconda3\envs\fate\lib\json\encoder.py", line 257, in iterencode
    return _iterencode(o, 0)
  File "c:\users\evan\anaconda3\envs\fate\lib\site-packages\flask\json\__init__.py", line 100, in default
    return _json.JSONEncoder.default(self, o)
  File "c:\users\evan\anaconda3\envs\fate\lib\json\encoder.py", line 179, in default
    raise TypeError(f'Object of type {o.__class__.__name__} '
TypeError: Object of type AddRecipeForm is not JSON serializable
2019-10-11 18:21:30,934 INFO: Fate startup [in C:\Users\Evan\documents\fate\app\__init__.py:46]
