2019-10-11 22:46:06,023 ERROR: Exception on /user/Malthador [GET] [in c:\users\evan\anaconda3\envs\fate\lib\site-packages\flask\app.py:1891]
Traceback (most recent call last):
  File "c:\users\evan\anaconda3\envs\fate\lib\site-packages\flask\app.py", line 2446, in wsgi_app
    response = self.full_dispatch_request()
  File "c:\users\evan\anaconda3\envs\fate\lib\site-packages\flask\app.py", line 1951, in full_dispatch_request
    rv = self.handle_user_exception(e)
  File "c:\users\evan\anaconda3\envs\fate\lib\site-packages\flask\app.py", line 1820, in handle_user_exception
    reraise(exc_type, exc_value, tb)
  File "c:\users\evan\anaconda3\envs\fate\lib\site-packages\flask\_compat.py", line 39, in reraise
    raise value
  File "c:\users\evan\anaconda3\envs\fate\lib\site-packages\flask\app.py", line 1949, in full_dispatch_request
    rv = self.dispatch_request()
  File "c:\users\evan\anaconda3\envs\fate\lib\site-packages\flask\app.py", line 1935, in dispatch_request
    return self.view_functions[rule.endpoint](**req.view_args)
  File "C:\Users\Evan\documents\fate\app\routes.py", line 62, in user
    return render_template('user.html', user=user, recipes=recipes)
  File "c:\users\evan\anaconda3\envs\fate\lib\site-packages\flask\templating.py", line 138, in render_template
    ctx.app.jinja_env.get_or_select_template(template_name_or_list),
  File "c:\users\evan\anaconda3\envs\fate\lib\site-packages\jinja2\environment.py", line 869, in get_or_select_template
    return self.get_template(template_name_or_list, parent, globals)
  File "c:\users\evan\anaconda3\envs\fate\lib\site-packages\jinja2\environment.py", line 830, in get_template
    return self._load_template(name, self.make_globals(globals))
  File "c:\users\evan\anaconda3\envs\fate\lib\site-packages\jinja2\environment.py", line 804, in _load_template
    template = self.loader.load(self, name, globals)
  File "c:\users\evan\anaconda3\envs\fate\lib\site-packages\jinja2\loaders.py", line 125, in load
    code = environment.compile(source, name, filename)
  File "c:\users\evan\anaconda3\envs\fate\lib\site-packages\jinja2\environment.py", line 591, in compile
    self.handle_exception(exc_info, source_hint=source_hint)
  File "c:\users\evan\anaconda3\envs\fate\lib\site-packages\jinja2\environment.py", line 780, in handle_exception
    reraise(exc_type, exc_value, tb)
  File "c:\users\evan\anaconda3\envs\fate\lib\site-packages\jinja2\_compat.py", line 37, in reraise
    raise value.with_traceback(tb)
  File "C:\Users\Evan\documents\fate\app\templates\user.html", line 22, in template
    {% if recipe.name != '' or not recipe.name is None %}
  File "c:\users\evan\anaconda3\envs\fate\lib\site-packages\jinja2\environment.py", line 543, in _generate
    optimized=self.optimized)
  File "c:\users\evan\anaconda3\envs\fate\lib\site-packages\jinja2\compiler.py", line 82, in generate
    generator.visit(node)
  File "c:\users\evan\anaconda3\envs\fate\lib\site-packages\jinja2\visitor.py", line 38, in visit
    return f(node, *args, **kwargs)
  File "c:\users\evan\anaconda3\envs\fate\lib\site-packages\jinja2\compiler.py", line 799, in visit_Template
    self.blockvisit(block.body, block_frame)
  File "c:\users\evan\anaconda3\envs\fate\lib\site-packages\jinja2\compiler.py", line 378, in blockvisit
    self.visit(node, frame)
  File "c:\users\evan\anaconda3\envs\fate\lib\site-packages\jinja2\visitor.py", line 38, in visit
    return f(node, *args, **kwargs)
  File "c:\users\evan\anaconda3\envs\fate\lib\site-packages\jinja2\compiler.py", line 1122, in visit_For
    self.blockvisit(node.body, loop_frame)
  File "c:\users\evan\anaconda3\envs\fate\lib\site-packages\jinja2\compiler.py", line 378, in blockvisit
    self.visit(node, frame)
  File "c:\users\evan\anaconda3\envs\fate\lib\site-packages\jinja2\visitor.py", line 38, in visit
    return f(node, *args, **kwargs)
  File "c:\users\evan\anaconda3\envs\fate\lib\site-packages\jinja2\compiler.py", line 1122, in visit_For
    self.blockvisit(node.body, loop_frame)
  File "c:\users\evan\anaconda3\envs\fate\lib\site-packages\jinja2\compiler.py", line 378, in blockvisit
    self.visit(node, frame)
  File "c:\users\evan\anaconda3\envs\fate\lib\site-packages\jinja2\visitor.py", line 38, in visit
    return f(node, *args, **kwargs)
  File "c:\users\evan\anaconda3\envs\fate\lib\site-packages\jinja2\compiler.py", line 1157, in visit_If
    self.visit(node.test, if_frame)
  File "c:\users\evan\anaconda3\envs\fate\lib\site-packages\jinja2\visitor.py", line 38, in visit
    return f(node, *args, **kwargs)
  File "c:\users\evan\anaconda3\envs\fate\lib\site-packages\jinja2\compiler.py", line 70, in new_func
    return f(self, node, frame, **kwargs)
  File "c:\users\evan\anaconda3\envs\fate\lib\site-packages\jinja2\compiler.py", line 1484, in visitor
    self.visit(node.right, frame)
  File "c:\users\evan\anaconda3\envs\fate\lib\site-packages\jinja2\visitor.py", line 38, in visit
    return f(node, *args, **kwargs)
  File "c:\users\evan\anaconda3\envs\fate\lib\site-packages\jinja2\compiler.py", line 70, in new_func
    return f(self, node, frame, **kwargs)
  File "c:\users\evan\anaconda3\envs\fate\lib\site-packages\jinja2\compiler.py", line 1497, in visitor
    self.visit(node.node, frame)
  File "c:\users\evan\anaconda3\envs\fate\lib\site-packages\jinja2\visitor.py", line 38, in visit
    return f(node, *args, **kwargs)
  File "c:\users\evan\anaconda3\envs\fate\lib\site-packages\jinja2\compiler.py", line 70, in new_func
    return f(self, node, frame, **kwargs)
  File "c:\users\evan\anaconda3\envs\fate\lib\site-packages\jinja2\compiler.py", line 1607, in visit_Test
    self.fail('no test named %r' % node.name, node.lineno)
  File "c:\users\evan\anaconda3\envs\fate\lib\site-packages\jinja2\compiler.py", line 315, in fail
    raise TemplateAssertionError(msg, lineno, self.name, self.filename)
jinja2.exceptions.TemplateAssertionError: no test named 'None'
2019-10-11 22:46:38,661 INFO: Fate startup [in C:\Users\Evan\documents\fate\app\__init__.py:46]
2019-10-11 22:49:30,484 INFO: Fate startup [in C:\Users\Evan\documents\fate\app\__init__.py:46]
2019-10-11 22:50:21,801 INFO: Fate startup [in C:\Users\Evan\documents\fate\app\__init__.py:46]
2019-10-11 22:51:55,546 INFO: Fate startup [in C:\Users\Evan\documents\fate\app\__init__.py:46]
2019-10-11 22:57:14,276 INFO: Fate startup [in C:\Users\Evan\documents\fate\app\__init__.py:46]
2019-10-11 22:57:17,705 INFO: Fate startup [in C:\Users\Evan\documents\fate\app\__init__.py:46]
2019-10-11 22:57:20,862 INFO: Fate startup [in C:\Users\Evan\documents\fate\app\__init__.py:46]
2019-10-11 22:58:53,046 INFO: Fate startup [in C:\Users\Evan\documents\fate\app\__init__.py:46]
2019-10-11 23:00:00,561 INFO: Fate startup [in C:\Users\Evan\documents\fate\app\__init__.py:46]
2019-10-12 00:03:10,779 INFO: Fate startup [in C:\Users\Evan\documents\fate\app\__init__.py:46]
2019-10-12 15:57:51,035 INFO: Fate startup [in C:\Users\Evan\documents\fate\app\__init__.py:46]
2019-10-12 16:00:41,904 INFO: Fate startup [in C:\Users\Evan\documents\fate\app\__init__.py:46]
2019-10-12 16:00:44,056 ERROR: Exception on /user/Malthador [GET] [in c:\users\evan\anaconda3\envs\fate\lib\site-packages\flask\app.py:1891]
Traceback (most recent call last):
  File "c:\users\evan\anaconda3\envs\fate\lib\site-packages\flask\app.py", line 2446, in wsgi_app
    response = self.full_dispatch_request()
  File "c:\users\evan\anaconda3\envs\fate\lib\site-packages\flask\app.py", line 1951, in full_dispatch_request
    rv = self.handle_user_exception(e)
  File "c:\users\evan\anaconda3\envs\fate\lib\site-packages\flask\app.py", line 1820, in handle_user_exception
    reraise(exc_type, exc_value, tb)
  File "c:\users\evan\anaconda3\envs\fate\lib\site-packages\flask\_compat.py", line 39, in reraise
    raise value
  File "c:\users\evan\anaconda3\envs\fate\lib\site-packages\flask\app.py", line 1949, in full_dispatch_request
    rv = self.dispatch_request()
  File "c:\users\evan\anaconda3\envs\fate\lib\site-packages\flask\app.py", line 1935, in dispatch_request
    return self.view_functions[rule.endpoint](**req.view_args)
  File "C:\Users\Evan\documents\fate\app\routes.py", line 56, in user
    recipes = ProfessionItem.query.filter_by(profession=profession).filter(ProfessionItem.skill_required>0).order_by(ProfessionItem.skill_required).all()
NameError: name 'profession' is not defined
2019-10-12 16:01:49,035 INFO: Fate startup [in C:\Users\Evan\documents\fate\app\__init__.py:46]
2019-10-12 16:15:26,352 INFO: Fate startup [in C:\Users\Evan\documents\fate\app\__init__.py:46]
