2019-10-11 02:02:59,792 ERROR: Exception on /recipes/Alchemy [GET] [in c:\users\evan\anaconda3\envs\fate\lib\site-packages\flask\app.py:1891]
Traceback (most recent call last):
  File "c:\users\evan\anaconda3\envs\fate\lib\site-packages\flask\app.py", line 2446, in wsgi_app
    response = self.full_dispatch_request()
  File "c:\users\evan\anaconda3\envs\fate\lib\site-packages\flask\app.py", line 1951, in full_dispatch_request
    rv = self.handle_user_exception(e)
  File "c:\users\evan\anaconda3\envs\fate\lib\site-packages\flask\app.py", line 1820, in handle_user_exception
    reraise(exc_type, exc_value, tb)
  File "c:\users\evan\anaconda3\envs\fate\lib\site-packages\flask\_compat.py", line 39, in reraise
    raise value
  File "c:\users\evan\anaconda3\envs\fate\lib\site-packages\flask\app.py", line 1949, in full_dispatch_request
    rv = self.dispatch_request()
  File "c:\users\evan\anaconda3\envs\fate\lib\site-packages\flask\app.py", line 1935, in dispatch_request
    return self.view_functions[rule.endpoint](**req.view_args)
  File "C:\Users\Evan\documents\fate\app\routes.py", line 82, in recipes
    return render_template('profession_recipes.html', recipes=recipes)
  File "c:\users\evan\anaconda3\envs\fate\lib\site-packages\flask\templating.py", line 140, in render_template
    ctx.app,
  File "c:\users\evan\anaconda3\envs\fate\lib\site-packages\flask\templating.py", line 120, in _render
    rv = template.render(context)
  File "c:\users\evan\anaconda3\envs\fate\lib\site-packages\jinja2\asyncsupport.py", line 76, in render
    return original_render(self, *args, **kwargs)
  File "c:\users\evan\anaconda3\envs\fate\lib\site-packages\jinja2\environment.py", line 1008, in render
    return self.environment.handle_exception(exc_info, True)
  File "c:\users\evan\anaconda3\envs\fate\lib\site-packages\jinja2\environment.py", line 780, in handle_exception
    reraise(exc_type, exc_value, tb)
  File "c:\users\evan\anaconda3\envs\fate\lib\site-packages\jinja2\_compat.py", line 37, in reraise
    raise value.with_traceback(tb)
  File "C:\Users\Evan\documents\fate\app\templates\profession_recipes.html", line 1, in top-level template code
    {% extends "base.html" %}
  File "c:\users\evan\anaconda3\envs\fate\lib\site-packages\jinja2\environment.py", line 1005, in render
    return concat(self.root_render_func(self.new_context(vars)))
  File "C:\Users\Evan\documents\fate\app\templates\profession_recipes.html", line 14, in root
  File "C:\Users\Evan\documents\fate\app\templates\base.html", line 14, in root
    <span class="icon-bar"></span>
  File "c:\users\evan\anaconda3\envs\fate\lib\site-packages\flask_bootstrap\templates\bootstrap\base.html", line 10, in root
    <meta name="viewport" content="width=device-width, initial-scale=1.0">
  File "c:\users\evan\anaconda3\envs\fate\lib\site-packages\flask_bootstrap\templates\bootstrap\base.html", line 20, in block_doc
    {% block body -%}
  File "c:\users\evan\anaconda3\envs\fate\lib\site-packages\flask_bootstrap\templates\bootstrap\base.html", line 39, in block_html
  File "c:\users\evan\anaconda3\envs\fate\lib\site-packages\flask_bootstrap\templates\bootstrap\base.html", line 90, in block_body
  File "C:\Users\Evan\documents\fate\app\templates\base.html", line 42, in block_navbar
    {% endfor %}
  File "c:\users\evan\anaconda3\envs\fate\lib\site-packages\jinja2\runtime.py", line 262, in call
    return __obj(*args, **kwargs)
  File "c:\users\evan\anaconda3\envs\fate\lib\site-packages\flask\helpers.py", line 370, in url_for
    return appctx.app.handle_url_build_error(error, endpoint, values)
  File "c:\users\evan\anaconda3\envs\fate\lib\site-packages\flask\app.py", line 2215, in handle_url_build_error
    reraise(exc_type, exc_value, tb)
  File "c:\users\evan\anaconda3\envs\fate\lib\site-packages\flask\_compat.py", line 39, in reraise
    raise value
  File "c:\users\evan\anaconda3\envs\fate\lib\site-packages\flask\helpers.py", line 358, in url_for
    endpoint, values, method=method, force_external=external
  File "c:\users\evan\anaconda3\envs\fate\lib\site-packages\werkzeug\routing.py", line 2020, in build
    raise BuildError(endpoint, values, method, self)
werkzeug.routing.BuildError: Could not build url for endpoint 'explore'. Did you mean 'edit_profile' instead?
2019-10-11 02:03:03,893 INFO: Fate startup [in C:\Users\Evan\documents\fate\app\__init__.py:46]
2019-10-11 02:03:51,798 INFO: Fate startup [in C:\Users\Evan\documents\fate\app\__init__.py:46]
2019-10-11 02:07:01,668 INFO: Fate startup [in C:\Users\Evan\documents\fate\app\__init__.py:46]
2019-10-11 02:08:04,264 INFO: Fate startup [in C:\Users\Evan\documents\fate\app\__init__.py:46]
2019-10-11 02:10:04,064 INFO: Fate startup [in C:\Users\Evan\documents\fate\app\__init__.py:46]
2019-10-11 02:17:54,985 INFO: Fate startup [in C:\Users\Evan\documents\fate\app\__init__.py:46]
2019-10-11 02:18:00,247 ERROR: Exception on /recipes/Alchemy [GET] [in c:\users\evan\anaconda3\envs\fate\lib\site-packages\flask\app.py:1891]
Traceback (most recent call last):
  File "c:\users\evan\anaconda3\envs\fate\lib\site-packages\flask\app.py", line 2446, in wsgi_app
    response = self.full_dispatch_request()
  File "c:\users\evan\anaconda3\envs\fate\lib\site-packages\flask\app.py", line 1951, in full_dispatch_request
    rv = self.handle_user_exception(e)
  File "c:\users\evan\anaconda3\envs\fate\lib\site-packages\flask\app.py", line 1820, in handle_user_exception
    reraise(exc_type, exc_value, tb)
  File "c:\users\evan\anaconda3\envs\fate\lib\site-packages\flask\_compat.py", line 39, in reraise
    raise value
  File "c:\users\evan\anaconda3\envs\fate\lib\site-packages\flask\app.py", line 1949, in full_dispatch_request
    rv = self.dispatch_request()
  File "c:\users\evan\anaconda3\envs\fate\lib\site-packages\flask\app.py", line 1935, in dispatch_request
    return self.view_functions[rule.endpoint](**req.view_args)
  File "C:\Users\Evan\documents\fate\app\routes.py", line 82, in recipes
    return render_template('profession_recipes.html', recipes=recipes)
  File "c:\users\evan\anaconda3\envs\fate\lib\site-packages\flask\templating.py", line 140, in render_template
    ctx.app,
  File "c:\users\evan\anaconda3\envs\fate\lib\site-packages\flask\templating.py", line 120, in _render
    rv = template.render(context)
  File "c:\users\evan\anaconda3\envs\fate\lib\site-packages\jinja2\asyncsupport.py", line 76, in render
    return original_render(self, *args, **kwargs)
  File "c:\users\evan\anaconda3\envs\fate\lib\site-packages\jinja2\environment.py", line 1008, in render
    return self.environment.handle_exception(exc_info, True)
  File "c:\users\evan\anaconda3\envs\fate\lib\site-packages\jinja2\environment.py", line 780, in handle_exception
    reraise(exc_type, exc_value, tb)
  File "c:\users\evan\anaconda3\envs\fate\lib\site-packages\jinja2\_compat.py", line 37, in reraise
    raise value.with_traceback(tb)
  File "C:\Users\Evan\documents\fate\app\templates\profession_recipes.html", line 1, in top-level template code
    {% extends "base.html" %}
  File "c:\users\evan\anaconda3\envs\fate\lib\site-packages\jinja2\environment.py", line 1005, in render
    return concat(self.root_render_func(self.new_context(vars)))
  File "C:\Users\Evan\documents\fate\app\templates\profession_recipes.html", line 14, in root
    </div>
  File "C:\Users\Evan\documents\fate\app\templates\base.html", line 14, in root
    <span class="icon-bar"></span>
  File "c:\users\evan\anaconda3\envs\fate\lib\site-packages\flask_bootstrap\templates\bootstrap\base.html", line 10, in root
    <meta name="viewport" content="width=device-width, initial-scale=1.0">
  File "c:\users\evan\anaconda3\envs\fate\lib\site-packages\flask_bootstrap\templates\bootstrap\base.html", line 20, in block_doc
    {% block body -%}
  File "c:\users\evan\anaconda3\envs\fate\lib\site-packages\flask_bootstrap\templates\bootstrap\base.html", line 39, in block_html
  File "c:\users\evan\anaconda3\envs\fate\lib\site-packages\flask_bootstrap\templates\bootstrap\base.html", line 92, in block_body
  File "C:\Users\Evan\documents\fate\app\templates\base.html", line 79, in block_content
  File "C:\Users\Evan\documents\fate\app\templates\profession_recipes.html", line 24, in block_app_content
    </div>
  File "c:\users\evan\anaconda3\envs\fate\lib\site-packages\jinja2\runtime.py", line 262, in call
    return __obj(*args, **kwargs)
  File "c:\users\evan\anaconda3\envs\fate\lib\site-packages\jinja2\runtime.py", line 630, in _fail_with_undefined_error
    raise self._undefined_exception(hint)
jinja2.exceptions.UndefinedError: 'enumerate' is undefined
2019-10-11 02:23:39,012 INFO: Fate startup [in C:\Users\Evan\documents\fate\app\__init__.py:46]
2019-10-11 02:26:47,551 INFO: Fate startup [in C:\Users\Evan\documents\fate\app\__init__.py:46]
2019-10-11 02:31:09,887 INFO: Fate startup [in C:\Users\Evan\documents\fate\app\__init__.py:46]
