2019-10-11 01:43:49,900 ERROR: Exception on /favicon.ico [GET] [in c:\users\evan\anaconda3\envs\fate\lib\site-packages\flask\app.py:1891]
Traceback (most recent call last):
  File "c:\users\evan\anaconda3\envs\fate\lib\site-packages\sqlalchemy\engine\base.py", line 1249, in _execute_context
    cursor, statement, parameters, context
  File "c:\users\evan\anaconda3\envs\fate\lib\site-packages\sqlalchemy\engine\default.py", line 580, in do_execute
    cursor.execute(statement, parameters)
sqlite3.OperationalError: no such column: user.profession_one

The above exception was the direct cause of the following exception:

Traceback (most recent call last):
  File "c:\users\evan\anaconda3\envs\fate\lib\site-packages\flask\app.py", line 2446, in wsgi_app
    response = self.full_dispatch_request()
  File "c:\users\evan\anaconda3\envs\fate\lib\site-packages\flask\app.py", line 1951, in full_dispatch_request
    rv = self.handle_user_exception(e)
  File "c:\users\evan\anaconda3\envs\fate\lib\site-packages\flask\app.py", line 1820, in handle_user_exception
    reraise(exc_type, exc_value, tb)
  File "c:\users\evan\anaconda3\envs\fate\lib\site-packages\flask\_compat.py", line 39, in reraise
    raise value
  File "c:\users\evan\anaconda3\envs\fate\lib\site-packages\flask\app.py", line 1947, in full_dispatch_request
    rv = self.preprocess_request()
  File "c:\users\evan\anaconda3\envs\fate\lib\site-packages\flask\app.py", line 2241, in preprocess_request
    rv = func()
  File "C:\Users\Evan\documents\fate\app\routes.py", line 10, in before_request
    if current_user.is_authenticated:
  File "c:\users\evan\anaconda3\envs\fate\lib\site-packages\werkzeug\local.py", line 348, in __getattr__
    return getattr(self._get_current_object(), name)
  File "c:\users\evan\anaconda3\envs\fate\lib\site-packages\werkzeug\local.py", line 307, in _get_current_object
    return self.__local()
  File "c:\users\evan\anaconda3\envs\fate\lib\site-packages\flask_login\utils.py", line 26, in <lambda>
    current_user = LocalProxy(lambda: _get_user())
  File "c:\users\evan\anaconda3\envs\fate\lib\site-packages\flask_login\utils.py", line 335, in _get_user
    current_app.login_manager._load_user()
  File "c:\users\evan\anaconda3\envs\fate\lib\site-packages\flask_login\login_manager.py", line 359, in _load_user
    return self.reload_user()
  File "c:\users\evan\anaconda3\envs\fate\lib\site-packages\flask_login\login_manager.py", line 321, in reload_user
    user = self.user_callback(user_id)
  File "C:\Users\Evan\documents\fate\app\models.py", line 55, in load_user
    return User.query.get(int(id))
  File "c:\users\evan\anaconda3\envs\fate\lib\site-packages\sqlalchemy\orm\query.py", line 959, in get
    return self._get_impl(ident, loading.load_on_pk_identity)
  File "c:\users\evan\anaconda3\envs\fate\lib\site-packages\sqlalchemy\orm\query.py", line 1069, in _get_impl
    return db_load_fn(self, primary_key_identity)
  File "c:\users\evan\anaconda3\envs\fate\lib\site-packages\sqlalchemy\orm\loading.py", line 282, in load_on_pk_identity
    return q.one()
  File "c:\users\evan\anaconda3\envs\fate\lib\site-packages\sqlalchemy\orm\query.py", line 3300, in one
    ret = self.one_or_none()
  File "c:\users\evan\anaconda3\envs\fate\lib\site-packages\sqlalchemy\orm\query.py", line 3269, in one_or_none
    ret = list(self)
  File "c:\users\evan\anaconda3\envs\fate\lib\site-packages\sqlalchemy\orm\query.py", line 3342, in __iter__
    return self._execute_and_instances(context)
  File "c:\users\evan\anaconda3\envs\fate\lib\site-packages\sqlalchemy\orm\query.py", line 3367, in _execute_and_instances
    result = conn.execute(querycontext.statement, self._params)
  File "c:\users\evan\anaconda3\envs\fate\lib\site-packages\sqlalchemy\engine\base.py", line 988, in execute
    return meth(self, multiparams, params)
  File "c:\users\evan\anaconda3\envs\fate\lib\site-packages\sqlalchemy\sql\elements.py", line 287, in _execute_on_connection
    return connection._execute_clauseelement(self, multiparams, params)
  File "c:\users\evan\anaconda3\envs\fate\lib\site-packages\sqlalchemy\engine\base.py", line 1107, in _execute_clauseelement
    distilled_params,
  File "c:\users\evan\anaconda3\envs\fate\lib\site-packages\sqlalchemy\engine\base.py", line 1253, in _execute_context
    e, statement, parameters, cursor, context
  File "c:\users\evan\anaconda3\envs\fate\lib\site-packages\sqlalchemy\engine\base.py", line 1473, in _handle_dbapi_exception
    util.raise_from_cause(sqlalchemy_exception, exc_info)
  File "c:\users\evan\anaconda3\envs\fate\lib\site-packages\sqlalchemy\util\compat.py", line 398, in raise_from_cause
    reraise(type(exception), exception, tb=exc_tb, cause=cause)
  File "c:\users\evan\anaconda3\envs\fate\lib\site-packages\sqlalchemy\util\compat.py", line 152, in reraise
    raise value.with_traceback(tb)
  File "c:\users\evan\anaconda3\envs\fate\lib\site-packages\sqlalchemy\engine\base.py", line 1249, in _execute_context
    cursor, statement, parameters, context
  File "c:\users\evan\anaconda3\envs\fate\lib\site-packages\sqlalchemy\engine\default.py", line 580, in do_execute
    cursor.execute(statement, parameters)
sqlalchemy.exc.OperationalError: (sqlite3.OperationalError) no such column: user.profession_one
[SQL: SELECT user.id AS user_id, user.username AS user_username, user.email AS user_email, user.password_hash AS user_password_hash, user.about_me AS user_about_me, user.last_seen AS user_last_seen, user.profession_one AS user_profession_one, user.profession_two AS user_profession_two 
FROM user 
WHERE user.id = ?]
[parameters: (1,)]
(Background on this error at: http://sqlalche.me/e/e3q8)
2019-10-11 01:44:13,426 INFO: Fate startup [in C:\Users\Evan\documents\fate\app\__init__.py:44]
2019-10-11 01:44:16,243 INFO: Fate startup [in C:\Users\Evan\documents\fate\app\__init__.py:44]
2019-10-11 01:44:18,662 INFO: Fate startup [in C:\Users\Evan\documents\fate\app\__init__.py:44]
2019-10-11 01:44:19,892 ERROR: Exception on /recipes/Alchemy [GET] [in c:\users\evan\anaconda3\envs\fate\lib\site-packages\flask\app.py:1891]
Traceback (most recent call last):
  File "c:\users\evan\anaconda3\envs\fate\lib\site-packages\flask\app.py", line 2446, in wsgi_app
    response = self.full_dispatch_request()
  File "c:\users\evan\anaconda3\envs\fate\lib\site-packages\flask\app.py", line 1951, in full_dispatch_request
    rv = self.handle_user_exception(e)
  File "c:\users\evan\anaconda3\envs\fate\lib\site-packages\flask\app.py", line 1820, in handle_user_exception
    reraise(exc_type, exc_value, tb)
  File "c:\users\evan\anaconda3\envs\fate\lib\site-packages\flask\_compat.py", line 39, in reraise
    raise value
  File "c:\users\evan\anaconda3\envs\fate\lib\site-packages\flask\app.py", line 1949, in full_dispatch_request
    rv = self.dispatch_request()
  File "c:\users\evan\anaconda3\envs\fate\lib\site-packages\flask\app.py", line 1935, in dispatch_request
    return self.view_functions[rule.endpoint](**req.view_args)
  File "C:\Users\Evan\documents\fate\app\routes.py", line 82, in recipes
    return render_template('profession_recipes.html', recipes=recipes)
  File "c:\users\evan\anaconda3\envs\fate\lib\site-packages\flask\templating.py", line 140, in render_template
    ctx.app,
  File "c:\users\evan\anaconda3\envs\fate\lib\site-packages\flask\templating.py", line 120, in _render
    rv = template.render(context)
  File "c:\users\evan\anaconda3\envs\fate\lib\site-packages\jinja2\asyncsupport.py", line 76, in render
    return original_render(self, *args, **kwargs)
  File "c:\users\evan\anaconda3\envs\fate\lib\site-packages\jinja2\environment.py", line 1008, in render
    return self.environment.handle_exception(exc_info, True)
  File "c:\users\evan\anaconda3\envs\fate\lib\site-packages\jinja2\environment.py", line 780, in handle_exception
    reraise(exc_type, exc_value, tb)
  File "c:\users\evan\anaconda3\envs\fate\lib\site-packages\jinja2\_compat.py", line 37, in reraise
    raise value.with_traceback(tb)
  File "C:\Users\Evan\documents\fate\app\templates\profession_recipes.html", line 1, in top-level template code
    {% extends "base.html" %}
  File "c:\users\evan\anaconda3\envs\fate\lib\site-packages\jinja2\environment.py", line 1005, in render
    return concat(self.root_render_func(self.new_context(vars)))
  File "C:\Users\Evan\documents\fate\app\templates\profession_recipes.html", line 14, in root
  File "C:\Users\Evan\documents\fate\app\templates\base.html", line 54, in root
  File "C:\Users\Evan\documents\fate\app\templates\profession_recipes.html", line 26, in block_content
  File "c:\users\evan\anaconda3\envs\fate\lib\site-packages\jinja2\environment.py", line 830, in get_template
    return self._load_template(name, self.make_globals(globals))
  File "c:\users\evan\anaconda3\envs\fate\lib\site-packages\jinja2\environment.py", line 804, in _load_template
    template = self.loader.load(self, name, globals)
  File "c:\users\evan\anaconda3\envs\fate\lib\site-packages\jinja2\loaders.py", line 113, in load
    source, filename, uptodate = self.get_source(environment, name)
  File "c:\users\evan\anaconda3\envs\fate\lib\site-packages\flask\templating.py", line 60, in get_source
    return self._get_source_fast(environment, template)
  File "c:\users\evan\anaconda3\envs\fate\lib\site-packages\flask\templating.py", line 89, in _get_source_fast
    raise TemplateNotFound(template)
jinja2.exceptions.TemplateNotFound: _post.html
2019-10-11 01:45:59,026 INFO: Fate startup [in C:\Users\Evan\documents\fate\app\__init__.py:44]
2019-10-11 01:47:34,938 INFO: Fate startup [in C:\Users\Evan\documents\fate\app\__init__.py:44]
